Workbook

Sheet Requisições FY26
A1: CONTROLE DE REQUISIÇÕES
H2: =IF(Table1[[#This Row],[PEDIDO]]<>"",_xlfn.XLOOKUP(Table1[[#This Row],[PEDIDO]],'[1]BASE DE VIM''s-NF''s'!I:I,'[1]BASE DE VIM''s-NF''s'!F:F,"-"),"-") -> #VALUE! | I2: =_xlfn.XLOOKUP(Table1[[#This Row],[VIM]],'[1]BASE DE VIM''s-NF''s'!F:F,'[1]BASE DE VIM''s-NF''s'!A:A,"") -> #VALUE! | J2: =_xlfn.XLOOKUP(Table1[[#This Row],[VIM]],'[1]BASE DE VIM''s-NF''s'!F:F,'[1]BASE DE VIM''s-NF''s'!L:L,"") -> #VALUE! | K2: =_xlfn.XLOOKUP(Table1[[#This Row],[VIM]],'[1]BASE DE VIM''s-NF''s'!F:F,'[1]BASE DE VIM''s-NF''s'!G:G,"") -> #VALUE! | M2: cancelado
A3: Coluna1 | B3: SOLICITANTE | C3: MODELO | D3: DESCRIÇÃO | E3: APROVADOR | F3: REQUISIÇÃO | G3: PEDIDO | H3: VIM | I3: STATUS VIM | J3: NOTA FISCAL | K3: FORNECEDOR | L3: DESPESA | M3: STATUS
A4: 45874 | B4: Erick | C4: Material | D4: Soquetes GEDORE | E4: Marco Stella | F4: 1076162433 | G4: 4501705723 | H4: =IF(Table1[[#This Row],[PEDIDO]]<>"",_xlfn.XLOOKUP(Table1[[#This Row],[PEDIDO]],'[1]BASE DE VIM''s-NF''s'!I:I,'[1]BASE DE VIM''s-NF''s'!F:F,"-"),"-") -> 2905857 | I4: =_xlfn.XLOOKUP(Table1[[#This Row],[VIM]],'[1]BASE DE VIM''s-NF''s'!F:F,'[1]BASE DE VIM''s-NF''s'!A:A,"") -> Lançado | J4: =_xlfn.XLOOKUP(Table1[[#This Row],[VIM]],'[1]BASE DE VIM''s-NF''s'!F:F,'[1]BASE DE VIM''s-NF''s'!L:L,"") -> 001438653-3 | K4: =_xlfn.XLOOKUP(Table1[[#This Row],[VIM]],'[1]BASE DE VIM''s-NF''s'!F:F,'[1]BASE DE VIM''s-NF''s'!G:G,"") -> ANHANGUERA COMERCIO DE | L4: =_xlfn.XLOOKUP(Table1[[#This Row],[PEDIDO]],'[1]BASE DE VIM''s-NF''s'!I:I,'[1]BASE DE VIM''s-NF''s'!R:R,"") -> 549.90 | M4: FINALIZADO
A5: 45874 | B5: Rafael | C5: Serviço | D5: Bate Rodas | E5: Marco Stella | F5: 1076202798 | G5: 4501706549 | H5: =IF(Table1[[#This Row],[PEDIDO]]<>"",_xlfn.XLOOKUP(Table1[[#This Row],[PEDIDO]],'[1]BASE DE VIM''s-NF''s'!I:I,'[1]BASE DE VIM''s-NF''s'!F:F,"-"),"-") -> 2925735 | I5: =_xlfn.XLOOKUP(Table1[[#This Row],[VIM]],'[1]BASE DE VIM''s-NF''s'!F:F,'[1]BASE DE VIM''s-NF''s'!A:A,"") -> Lançado | J5: =_xlfn.XLOOKUP(Table1[[#This Row],[VIM]],'[1]BASE DE VIM''s-NF''s'!F:F,'[1]BASE DE VIM''s-NF''s'!L:L,"") -> 000000689-9 | K5: =_xlfn.XLOOKUP(Table1[[#This Row],[VIM]],'[1]BASE DE VIM''s-NF''s'!F:F,'[1]BASE DE VIM''s-NF''s'!G:G,"") -> ESTRUTURAS E EQUIPAMENTOS | L5: =_xlfn.XLOOKUP(Table1[[#This Row],[PEDIDO]],'[1]BASE DE VIM''s-NF''s'!I:I,'[1]BASE DE VIM''s-NF''s'!R:R,"") -> 1,800.00 | M5: FINALIZADO
A6: 45881 | B6: Amanda | C6: Material | D6: Materiais Papel e Pintura | E6: Marco Stella | F6: 1076285290 | G6: 4501706360 | H6: =IF(Table1[[#This Row],[PEDIDO]]<>"",_xlfn.XLOOKUP(Table1[[#This Row],[PEDIDO]],'[1]BASE DE VIM''s-NF''s'!I:I,'[1]BASE DE VIM''s-NF''s'!F:F,"-"),"-") -> 2928122 | I6: =_xlfn.XLOOKUP(Table1[[#This Row],[VIM]],'[1]BASE DE VIM''s-NF''s'!F:F,'[1]BASE DE VIM''s-NF''s'!A:A,"") -> Lançado | J6: =_xlfn.XLOOKUP(Table1[[#This Row],[VIM]],'[1]BASE DE VIM''s-NF''s'!F:F,'[1]BASE DE VIM''s-NF''s'!L:L,"") -> 000126316-1 | K6: =_xlfn.XLOOKUP(Table1[[#This Row],[VIM]],'[1]BASE DE VIM''s-NF''s'!F:F,'[1]BASE DE VIM''s-NF''s'!G:G,"") -> TIAGO DE BROI EIRELI EPP. | L6: =_xlfn.XLOOKUP(Table1[[#This Row],[PEDIDO]],'[1]BASE DE VIM''s-NF''s'!I:I,'[1]BASE DE VIM''s-NF''s'!R:R,"") -> 1,271.68 | M6: FINALIZADO
A7: 45881 | B7: Erick | C7: Material | D7: Bujão em SAE 4340 | E7: Marco Stella | F7: 1076285378 | G7: 4501706362 | H7: =IF(Table1[[#This Row],[PEDIDO]]<>"",_xlfn.XLOOKUP(Table1[[#This Row],[PEDIDO]],'[1]BASE DE VIM''s-NF''s'!I:I,'[1]BASE DE VIM''s-NF''s'!F:F,"-"),"-") -> 2928500 | I7: =_xlfn.XLOOKUP(Table1[[#This Row],[VIM]],'[1]BASE DE VIM''s-NF''s'!F:F,'[1]BASE DE VIM''s-NF''s'!A:A,"") -> Lançado | J7: =_xlfn.XLOOKUP(Table1[[#This Row],[VIM]],'[1]BASE DE VIM''s-NF''s'!F:F,'[1]BASE DE VIM''s-NF''s'!L:L,"") -> 000003214-1 | K7: =_xlfn.XLOOKUP(Table1[[#This Row],[VIM]],'[1]BASE DE VIM''s-NF''s'!F:F,'[1]BASE DE VIM''s-NF''s'!G:G,"") -> ZAP USINAGEM E CALDEIRARIA | L7: =_xlfn.XLOOKUP(Table1[[#This Row],[PEDIDO]],'[1]BASE DE VIM''s-NF''s'!I:I,'[1]BASE DE VIM''s-NF''s'!R:R,"") -> 653.29 | M7: FINALIZADO
A8: 45881 | B8: Erick | C8: Material | D8: Luva espaçadora impregnação | E8: Marco Stella | F8: 1076285394 | G8: 4501706365 | H8: =IF(Table1[[#This Row],[PEDIDO]]<>"",_xlfn.XLOOKUP(Table1[[#This Row],[PEDIDO]],'[1]BASE DE VIM''s-NF''s'!I:I,'[1]BASE DE VIM''s-NF''s'!F:F,"-"),"-") -> 2928499 | I8: =_xlfn.XLOOKUP(Table1[[#This Row],[VIM]],'[1]BASE DE VIM''s-NF''s'!F:F,'[1]BASE DE VIM''s-NF''s'!A:A,"") -> Lançado | J8: =_xlfn.XLOOKUP(Table1[[#This Row],[VIM]],'[1]BASE DE VIM''s-NF''s'!F:F,'[1]BASE DE VIM''s-NF''s'!L:L,"") -> 000003215-1 | K8: =_xlfn.XLOOKUP(Table1[[#This Row],[VIM]],'[1]BASE DE VIM''s-NF''s'!F:F,'[1]BASE DE VIM''s-NF''s'!G:G,"") -> ZAP USINAGEM E CALDEIRARIA | L8: =_xlfn.XLOOKUP(Table1[[#This Row],[PEDIDO]],'[1]BASE DE VIM''s-NF''s'!I:I,'[1]BASE DE VIM''s-NF''s'!R:R,"") -> 2,298.62 | M8: FINALIZADO
A9: 45888 | B9: Amanda | C9: Material | D9: Adaptador T | E9: Marco Stella | F9: 1076351664 | G9: 4501706868 | H9: =IF(Table1[[#This Row],[PEDIDO]]<>"",_xlfn.XLOOKUP(Table1[[#This Row],[PEDIDO]],'[1]BASE DE VIM''s-NF''s'!I:I,'[1]BASE DE VIM''s-NF''s'!F:F,"-"),"-") -> 2912973 | I9: =_xlfn.XLOOKUP(Table1[[#This Row],[VIM]],'[1]BASE DE VIM''s-NF''s'!F:F,'[1]BASE DE VIM''s-NF''s'!A:A,"") -> Lançado | J9: =_xlfn.XLOOKUP(Table1[[#This Row],[VIM]],'[1]BASE DE VIM''s-NF''s'!F:F,'[1]BASE DE VIM''s-NF''s'!L:L,"") -> 000123643-1 | K9: =_xlfn.XLOOKUP(Table1[[#This Row],[VIM]],'[1]BASE DE VIM''s-NF''s'!F:F,'[1]BASE DE VIM''s-NF''s'!G:G,"") -> TIAGO DE BROI EIRELI EPP. | L9: =_xlfn.XLOOKUP(Table1[[#This Row],[PEDIDO]],'[1]BASE DE VIM''s-NF''s'!I:I,'[1]BASE DE VIM''s-NF''s'!R:R,"") -> 648.30 | M9: FINALIZADO
A10: 45888 | B10: Amanda | C10: Material | D10: BOTIJAO AREZZO e materias | E10: Marco Stella | F10: 1076351666 | G10: 4501706869 | H10: =IF(Table1[[#This Row],[PEDIDO]]<>"",_xlfn.XLOOKUP(Table1[[#This Row],[PEDIDO]],'[1]BASE DE VIM''s-NF''s'!I:I,'[1]BASE DE VIM''s-NF''s'!F:F,"-"),"-") -> 2913952 | I10: =_xlfn.XLOOKUP(Table1[[#This Row],[VIM]],'[1]BASE DE VIM''s-NF''s'!F:F,'[1]BASE DE VIM''s-NF''s'!A:A,"") -> Lançado | J10: =_xlfn.XLOOKUP(Table1[[#This Row],[VIM]],'[1]BASE DE VIM''s-NF''s'!F:F,'[1]BASE DE VIM''s-NF''s'!L:L,"") -> 000123798-1 | K10: =_xlfn.XLOOKUP(Table1[[#This Row],[VIM]],'[1]BASE DE VIM''s-NF''s'!F:F,'[1]BASE DE VIM''s-NF''s'!G:G,"") -> TIAGO DE BROI EIRELI EPP. | L10: =_xlfn.XLOOKUP(Table1[[#This Row],[PEDIDO]],'[1]BASE DE VIM''s-NF''s'!I:I,'[1]BASE DE VIM''s-NF''s'!R:R,"") -> 1,320.95 | M10: FINALIZADO
A11: 45888 | B11: Erick | C11: Material | D11: CONDUITE DO CABO SOLDA | E11: Marco Stella | F11: 1076351698 | G11: 4501706875 | H11: =IF(Table1[[#This Row],[PEDIDO]]<>"",_xlfn.XLOOKUP(Table1[[#This Row],[PEDIDO]],'[1]BASE DE VIM''s-NF''s'!I:I,'[1]BASE DE VIM''s-NF''s'!F:F,"-"),"-") -> 2910776 | I11: =_xlfn.XLOOKUP(Table1[[#This Row],[VIM]],'[1]BASE DE VIM''s-NF''s'!F:F,'[1]BASE DE VIM''s-NF''s'!A:A,"") -> Lançado | J11: =_xlfn.XLOOKUP(Table1[[#This Row],[VIM]],'[1]BASE DE VIM''s-NF''s'!F:F,'[1]BASE DE VIM''s-NF''s'!L:L,"") -> 000077661-1 | K11: =_xlfn.XLOOKUP(Table1[[#This Row],[VIM]],'[1]BASE DE VIM''s-NF''s'!F:F,'[1]BASE DE VIM''s-NF''s'!G:G,"") -> ENERGYARC INDUSTRIAL LTDA. | L11: =_xlfn.XLOOKUP(Table1[[#This Row],[PEDIDO]],'[1]BASE DE VIM''s-NF''s'!I:I,'[1]BASE DE VIM''s-NF''s'!R:R,"") -> 2,350.00 | M11: FINALIZADO
A12: 45890 | B12: Erick | C12: Material | D12: CA131130 - Bucha Guia de Bronze | E12: Marco Stella | F12: 1076385710 | G12: 4501707459 | H12: =IF(Table1[[#This Row],[PEDIDO]]<>"",_xlfn.XLOOKUP(Table1[[#This Row],[PEDIDO]],'[1]BASE DE VIM''s-NF''s'!I:I,'[1]BASE DE VIM''s-NF''s'!F:F,"-"),"-") -> 2916741 | I12: =_xlfn.XLOOKUP(Table1[[#This Row],[VIM]],'[1]BASE DE VIM''s-NF''s'!F:F,'[1]BASE DE VIM''s-NF''s'!A:A,"") -> Lançado | J12: =_xlfn.XLOOKUP(Table1[[#This Row],[VIM]],'[1]BASE DE VIM''s-NF''s'!F:F,'[1]BASE DE VIM''s-NF''s'!L:L,"") -> 000000891-1 | K12: =_xlfn.XLOOKUP(Table1[[#This Row],[VIM]],'[1]BASE DE VIM''s-NF''s'!F:F,'[1]BASE DE VIM''s-NF''s'!G:G,"") -> MB - COMERCIO E PRESTACAO DE SERVIC | L12: =_xlfn.XLOOKUP(Table1[[#This Row],[PEDIDO]],'[1]BASE DE VIM''s-NF''s'!I:I,'[1]BASE DE VIM''s-NF''s'!R:R,"") -> 1,425.60 | M12: FINALIZADO
A13: 45896 | B13: Erick | C13: Material | D13: CA131275 - Trava para capacitores REV02 | E13: Marco Stella | F13: 1076455040 | G13: 4501707908 | H13: =IF(Table1[[#This Row],[PEDIDO]]<>"",_xlfn.XLOOKUP(Table1[[#This Row],[PEDIDO]],'[1]BASE DE VIM''s-NF''s'!I:I,'[1]BASE DE VIM''s-NF''s'!F:F,"-"),"-") -> 2926678 | I13: =_xlfn.XLOOKUP(Table1[[#This Row],[VIM]],'[1]BASE DE VIM''s-NF''s'!F:F,'[1]BASE DE VIM''s-NF''s'!A:A,"") -> Lançado | J13: =_xlfn.XLOOKUP(Table1[[#This Row],[VIM]],'[1]BASE DE VIM''s-NF''s'!F:F,'[1]BASE DE VIM''s-NF''s'!L:L,"") -> 000006918-1 | K13: =_xlfn.XLOOKUP(Table1[[#This Row],[VIM]],'[1]BASE DE VIM''s-NF''s'!F:F,'[1]BASE DE VIM''s-NF''s'!G:G,"") -> MOTA - USINAGEM E | L13: =_xlfn.XLOOKUP(Table1[[#This Row],[PEDIDO]],'[1]BASE DE VIM''s-NF''s'!I:I,'[1]BASE DE VIM''s-NF''s'!R:R,"") -> 21,965.00 | M13: FINALIZADO
A14: 45896 | B14: Erick | C14: Serviço | D14: Serviço de remoção, carregamento, transporte interno | E14: Marco Stella | F14: 1076455045 | G14: 4501707839 | H14: =IF(Table1[[#This Row],[PEDIDO]]<>"",_xlfn.XLOOKUP(Table1[[#This Row],[PEDIDO]],'[1]BASE DE VIM''s-NF''s'!I:I,'[1]BASE DE VIM''s-NF''s'!F:F,"-"),"-") -> 2920168 | I14: =_xlfn.XLOOKUP(Table1[[#This Row],[VIM]],'[1]BASE DE VIM''s-NF''s'!F:F,'[1]BASE DE VIM''s-NF''s'!A:A,"") -> Lançado | J14: =_xlfn.XLOOKUP(Table1[[#This Row],[VIM]],'[1]BASE DE VIM''s-NF''s'!F:F,'[1]BASE DE VIM''s-NF''s'!L:L,"") -> 000004793-9 | K14: =_xlfn.XLOOKUP(Table1[[#This Row],[VIM]],'[1]BASE DE VIM''s-NF''s'!F:F,'[1]BASE DE VIM''s-NF''s'!G:G,"") -> TRANSPORTADORA GALIEGO LTDA. EPP. | L14: =_xlfn.XLOOKUP(Table1[[#This Row],[PEDIDO]],'[1]BASE DE VIM''s-NF''s'!I:I,'[1]BASE DE VIM''s-NF''s'!R:R,"") -> 20,150.00 | M14: FINALIZADO
A15: 45897 | B15: Erick | C15: OI | D15: TRANSPALETE 2500KG (Paleteiras) | E15: Marco Stella | F15: 1076499222 | G15: 4501708373 | H15: =IF(Table1[[#This Row],[PEDIDO]]<>"",_xlfn.XLOOKUP(Table1[[#This Row],[PEDIDO]],'[1]BASE DE VIM''s-NF''s'!I:I,'[1]BASE DE VIM''s-NF''s'!F:F,"-"),"-") -> 2922134 | I15: =_xlfn.XLOOKUP(Table1[[#This Row],[VIM]],'[1]BASE DE VIM''s-NF''s'!F:F,'[1]BASE DE VIM''s-NF''s'!A:A,"") -> Lançado | J15: =_xlfn.XLOOKUP(Table1[[#This Row],[VIM]],'[1]BASE DE VIM''s-NF''s'!F:F,'[1]BASE DE VIM''s-NF''s'!L:L,"") -> 001464300-3 | K15: =_xlfn.XLOOKUP(Table1[[#This Row],[VIM]],'[1]BASE DE VIM''s-NF''s'!F:F,'[1]BASE DE VIM''s-NF''s'!G:G,"") -> ANHANGUERA COMERCIO DE | L15: =_xlfn.XLOOKUP(Table1[[#This Row],[PEDIDO]],'[1]BASE DE VIM''s-NF''s'!I:I,'[1]BASE DE VIM''s-NF''s'!R:R,"") -> 12,990.00 | M15: FINALIZADO
A16: 45897 | B16: Erick | C16: OI | D16: Suporte carros de PP 012460; 012461 | E16: Marco Stella | F16: 1076499234 | G16: 4501708371 | H16: =IF(Table1[[#This Row],[PEDIDO]]<>"",_xlfn.XLOOKUP(Table1[[#This Row],[PEDIDO]],'[1]BASE DE VIM''s-NF''s'!I:I,'[1]BASE DE VIM''s-NF''s'!F:F,"-"),"-") -> 2951599 | I16: =_xlfn.XLOOKUP(Table1[[#This Row],[VIM]],'[1]BASE DE VIM''s-NF''s'!F:F,'[1]BASE DE VIM''s-NF''s'!A:A,"") -> Lançado | J16: =_xlfn.XLOOKUP(Table1[[#This Row],[VIM]],'[1]BASE DE VIM''s-NF''s'!F:F,'[1]BASE DE VIM''s-NF''s'!L:L,"") -> 000000365-9 | K16: =_xlfn.XLOOKUP(Table1[[#This Row],[VIM]],'[1]BASE DE VIM''s-NF''s'!F:F,'[1]BASE DE VIM''s-NF''s'!G:G,"") -> USINAGEM PAULISTA LTDA. | L16: =_xlfn.XLOOKUP(Table1[[#This Row],[PEDIDO]],'[1]BASE DE VIM''s-NF''s'!I:I,'[1]BASE DE VIM''s-NF''s'!R:R,"") -> 11,600.00 | M16: FINALIZADO
A17: 45897 | B17: Erick | C17: OI | D17: Adequação NR12 Ensaio BT 012632 | E17: Marco Stella | F17: 1076499309 | G17: 4501708628 | H17: =IF(Table1[[#This Row],[PEDIDO]]<>"",_xlfn.XLOOKUP(Table1[[#This Row],[PEDIDO]],'[1]BASE DE VIM''s-NF''s'!I:I,'[1]BASE DE VIM''s-NF''s'!F:F,"-"),"-") -> 2993920 | J17: =_xlfn.XLOOKUP(Table1[[#This Row],[VIM]],'[1]BASE DE VIM''s-NF''s'!F:F,'[1]BASE DE VIM''s-NF''s'!L:L,"") -> 000010140-1 | K17: =_xlfn.XLOOKUP(Table1[[#This Row],[VIM]],'[1]BASE DE VIM''s-NF''s'!F:F,'[1]BASE DE VIM''s-NF''s'!G:G,"") -> AUTOMASAFETY CONSULTORIA IND. E | L17: =_xlfn.XLOOKUP(Table1[[#This Row],[PEDIDO]],'[1]BASE DE VIM''s-NF''s'!I:I,'[1]BASE DE VIM''s-NF''s'!R:R,"") -> 132,011.20 | M17: FINALIZADO
A18: 45897 | B18: Erick | C18: OI | D18: NR12 Estufa Heat Soaking 03 012096 | E18: Marco Stella | F18: 1076499220 | G18: 4501708729 | H18: =IF(Table1[[#This Row],[PEDIDO]]<>"",_xlfn.XLOOKUP(Table1[[#This Row],[PEDIDO]],'[1]BASE DE VIM''s-NF''s'!I:I,'[1]BASE DE VIM''s-NF''s'!F:F,"-"),"-") -> 2966026 | I18: =_xlfn.XLOOKUP(Table1[[#This Row],[VIM]],'[1]BASE DE VIM''s-NF''s'!F:F,'[1]BASE DE VIM''s-NF''s'!A:A,"") -> Lançado | J18: =_xlfn.XLOOKUP(Table1[[#This Row],[VIM]],'[1]BASE DE VIM''s-NF''s'!F:F,'[1]BASE DE VIM''s-NF''s'!L:L,"") -> 000001083-9 | K18: =_xlfn.XLOOKUP(Table1[[#This Row],[VIM]],'[1]BASE DE VIM''s-NF''s'!F:F,'[1]BASE DE VIM''s-NF''s'!G:G,"") -> AUTOMASAFETY CONSULTORIA IND. E | L18: =_xlfn.XLOOKUP(Table1[[#This Row],[PEDIDO]],'[1]BASE DE VIM''s-NF''s'!I:I,'[1]BASE DE VIM''s-NF''s'!R:R,"") -> 17,430.70 | M18: FINALIZADO
A19: 45897 | B19: Erick | C19: OI | D19: Carro inox com prateleiras | E19: Marco Stella | F19: 1076499227 | G19: 4501708373 | H19: =IF(Table1[[#This Row],[PEDIDO]]<>"",_xlfn.XLOOKUP(Table1[[#This Row],[PEDIDO]],'[1]BASE DE VIM''s-NF''s'!I:I,'[1]BASE DE VIM''s-NF''s'!F:F,"-"),"-") -> 2922134 | I19: =_xlfn.XLOOKUP(Table1[[#This Row],[VIM]],'[1]BASE DE VIM''s-NF''s'!F:F,'[1]BASE DE VIM''s-NF''s'!A:A,"") -> Lançado | J19: =_xlfn.XLOOKUP(Table1[[#This Row],[VIM]],'[1]BASE DE VIM''s-NF''s'!F:F,'[1]BASE DE VIM''s-NF''s'!L:L,"") -> 001464300-3 | K19: =_xlfn.XLOOKUP(Table1[[#This Row],[VIM]],'[1]BASE DE VIM''s-NF''s'!F:F,'[1]BASE DE VIM''s-NF''s'!G:G,"") -> ANHANGUERA COMERCIO DE | L19: =_xlfn.XLOOKUP(Table1[[#This Row],[PEDIDO]],'[1]BASE DE VIM''s-NF''s'!I:I,'[1]BASE DE VIM''s-NF''s'!R:R,"") -> 12,990.00 | M19: FINALIZADO
A20: 45897 | B20: Erick | C20: OI | D20: Carro tanque pintura | E20: Marco Stella | F20: 1076499224 | G20: 4501708379 | H20: =IF(Table1[[#This Row],[PEDIDO]]<>"",_xlfn.XLOOKUP(Table1[[#This Row],[PEDIDO]],'[1]BASE DE VIM''s-NF''s'!I:I,'[1]BASE DE VIM''s-NF''s'!F:F,"-"),"-") -> 2962330 | I20: =_xlfn.XLOOKUP(Table1[[#This Row],[VIM]],'[1]BASE DE VIM''s-NF''s'!F:F,'[1]BASE DE VIM''s-NF''s'!A:A,"") -> Lançado | J20: =_xlfn.XLOOKUP(Table1[[#This Row],[VIM]],'[1]BASE DE VIM''s-NF''s'!F:F,'[1]BASE DE VIM''s-NF''s'!L:L,"") -> 000001173-1 | K20: =_xlfn.XLOOKUP(Table1[[#This Row],[VIM]],'[1]BASE DE VIM''s-NF''s'!F:F,'[1]BASE DE VIM''s-NF''s'!G:G,"") -> CONDUTA - E.R.C. SOLUCOES | L20: =_xlfn.XLOOKUP(Table1[[#This Row],[PEDIDO]],'[1]BASE DE VIM''s-NF''s'!I:I,'[1]BASE DE VIM''s-NF''s'!R:R,"") -> 11,400.00 | M20: FINALIZADO
A21: 45897 | B21: Erick | C21: OI | D21: Sistema de pintura Airless | E21: Marco Stella | F21: 1076530490 | G21: 4501708631 | H21: =IF(Table1[[#This Row],[PEDIDO]]<>"",_xlfn.XLOOKUP(Table1[[#This Row],[PEDIDO]],'[1]BASE DE VIM''s-NF''s'!I:I,'[1]BASE DE VIM''s-NF''s'!F:F,"-"),"-") -> 2947326 | J21: =_xlfn.XLOOKUP(Table1[[#This Row],[VIM]],'[1]BASE DE VIM''s-NF''s'!F:F,'[1]BASE DE VIM''s-NF''s'!L:L,"") -> 000018404-1 | K21: =_xlfn.XLOOKUP(Table1[[#This Row],[VIM]],'[1]BASE DE VIM''s-NF''s'!F:F,'[1]BASE DE VIM''s-NF''s'!G:G,"") -> FLOWSISTEM SOLUCOES | L21: =_xlfn.XLOOKUP(Table1[[#This Row],[PEDIDO]],'[1]BASE DE VIM''s-NF''s'!I:I,'[1]BASE DE VIM''s-NF''s'!R:R,"") -> 179,352.02
A22: 45897 | B22: Erick | C22: OI | D22: Mandíbula de cravação | E22: Marco Stella | F22: 1076499226 | G22: 4501708378 | H22: =IF(Table1[[#This Row],[PEDIDO]]<>"",_xlfn.XLOOKUP(Table1[[#This Row],[PEDIDO]],'[1]BASE DE VIM''s-NF''s'!I:I,'[1]BASE DE VIM''s-NF''s'!F:F,"-"),"-") -> 2921170 | I22: =_xlfn.XLOOKUP(Table1[[#This Row],[VIM]],'[1]BASE DE VIM''s-NF''s'!F:F,'[1]BASE DE VIM''s-NF''s'!A:A,"") -> Lançado | J22: =_xlfn.XLOOKUP(Table1[[#This Row],[VIM]],'[1]BASE DE VIM''s-NF''s'!F:F,'[1]BASE DE VIM''s-NF''s'!L:L,"") -> 000033924-1 | K22: =_xlfn.XLOOKUP(Table1[[#This Row],[VIM]],'[1]BASE DE VIM''s-NF''s'!F:F,'[1]BASE DE VIM''s-NF''s'!G:G,"") -> HILTI DO BRASIL COMERCIAL LTDA. | L22: =_xlfn.XLOOKUP(Table1[[#This Row],[PEDIDO]],'[1]BASE DE VIM''s-NF''s'!I:I,'[1]BASE DE VIM''s-NF''s'!R:R,"") -> 15,894.51 | M22: FINALIZADO
A23: 45897 | B23: Erick | C23: OI | D23: Capas de eixo | E23: Marco Stella | F23: 1076596908 | G23: 4501709214 | H23: =IF(Table1[[#This Row],[PEDIDO]]<>"",_xlfn.XLOOKUP(Table1[[#This Row],[PEDIDO]],'[1]BASE DE VIM''s-NF''s'!I:I,'[1]BASE DE VIM''s-NF''s'!F:F,"-"),"-") -> 2956948 | I23: =_xlfn.XLOOKUP(Table1[[#This Row],[VIM]],'[1]BASE DE VIM''s-NF''s'!F:F,'[1]BASE DE VIM''s-NF''s'!A:A,"") -> Lançado | J23: =_xlfn.XLOOKUP(Table1[[#This Row],[VIM]],'[1]BASE DE VIM''s-NF''s'!F:F,'[1]BASE DE VIM''s-NF''s'!L:L,"") -> 000007284-1 | K23: =_xlfn.XLOOKUP(Table1[[#This Row],[VIM]],'[1]BASE DE VIM''s-NF''s'!F:F,'[1]BASE DE VIM''s-NF''s'!G:G,"") -> ROVAMEC USINAGEM LTDA. EPP. | L23: =_xlfn.XLOOKUP(Table1[[#This Row],[PEDIDO]],'[1]BASE DE VIM''s-NF''s'!I:I,'[1]BASE DE VIM''s-NF''s'!R:R,"") -> 48,400.00 | M23: FINALIZADO
A24: 45901 | B24: Erick | C24: Material | D24: Materiais pintura e papel | E24: Marco Stella | F24: 1076530492 | G24: 4501708601 | H24: =IF(Table1[[#This Row],[PEDIDO]]<>"",_xlfn.XLOOKUP(Table1[[#This Row],[PEDIDO]],'[1]BASE DE VIM''s-NF''s'!I:I,'[1]BASE DE VIM''s-NF''s'!F:F,"-"),"-") -> 2917249 | I24: =_xlfn.XLOOKUP(Table1[[#This Row],[VIM]],'[1]BASE DE VIM''s-NF''s'!F:F,'[1]BASE DE VIM''s-NF''s'!A:A,"") -> Lançado | J24: =_xlfn.XLOOKUP(Table1[[#This Row],[VIM]],'[1]BASE DE VIM''s-NF''s'!F:F,'[1]BASE DE VIM''s-NF''s'!L:L,"") -> 000124468-1 | K24: =_xlfn.XLOOKUP(Table1[[#This Row],[VIM]],'[1]BASE DE VIM''s-NF''s'!F:F,'[1]BASE DE VIM''s-NF''s'!G:G,"") -> TIAGO DE BROI EIRELI EPP. | L24: =_xlfn.XLOOKUP(Table1[[#This Row],[PEDIDO]],'[1]BASE DE VIM''s-NF''s'!I:I,'[1]BASE DE VIM''s-NF''s'!R:R,"") -> 1,665.06 | M24: FINALIZADO
A25: 45903 | B25: Erick | C25: Material | D25: DISPOSITIVO FIXAÇÃO ROSCA M6 E M10 | E25: Marco Stella | F25: 1076574761 | G25: 4501708692 | H25: =IF(Table1[[#This Row],[PEDIDO]]<>"",_xlfn.XLOOKUP(Table1[[#This Row],[PEDIDO]],'[1]BASE DE VIM''s-NF''s'!I:I,'[1]BASE DE VIM''s-NF''s'!F:F,"-"),"-") -> 2917634 | I25: =_xlfn.XLOOKUP(Table1[[#This Row],[VIM]],'[1]BASE DE VIM''s-NF''s'!F:F,'[1]BASE DE VIM''s-NF''s'!A:A,"") -> Lançado | J25: =_xlfn.XLOOKUP(Table1[[#This Row],[VIM]],'[1]BASE DE VIM''s-NF''s'!F:F,'[1]BASE DE VIM''s-NF''s'!L:L,"") -> 000007167-1 | K25: =_xlfn.XLOOKUP(Table1[[#This Row],[VIM]],'[1]BASE DE VIM''s-NF''s'!F:F,'[1]BASE DE VIM''s-NF''s'!G:G,"") -> ROVAMEC USINAGEM LTDA. EPP. | L25: =_xlfn.XLOOKUP(Table1[[#This Row],[PEDIDO]],'[1]BASE DE VIM''s-NF''s'!I:I,'[1]BASE DE VIM''s-NF''s'!R:R,"") -> 420.00 | M25: FINALIZADO
A26: 45903 | B26: Erick | C26: Material | D26: ESCADA ALUMINIO ALULEV INDUSTRIAL Pintura | E26: Marco Stella | F26: 1076574775 | G26: 4501708871 | H26: =IF(Table1[[#This Row],[PEDIDO]]<>"",_xlfn.XLOOKUP(Table1[[#This Row],[PEDIDO]],'[1]BASE DE VIM''s-NF''s'!I:I,'[1]BASE DE VIM''s-NF''s'!F:F,"-"),"-") -> 2919812 | I26: =_xlfn.XLOOKUP(Table1[[#This Row],[VIM]],'[1]BASE DE VIM''s-NF''s'!F:F,'[1]BASE DE VIM''s-NF''s'!A:A,"") -> Lançado | J26: =_xlfn.XLOOKUP(Table1[[#This Row],[VIM]],'[1]BASE DE VIM''s-NF''s'!F:F,'[1]BASE DE VIM''s-NF''s'!L:L,"") -> 000124913-1 | K26: =_xlfn.XLOOKUP(Table1[[#This Row],[VIM]],'[1]BASE DE VIM''s-NF''s'!F:F,'[1]BASE DE VIM''s-NF''s'!G:G,"") -> TIAGO DE BROI EIRELI EPP. | L26: =_xlfn.XLOOKUP(Table1[[#This Row],[PEDIDO]],'[1]BASE DE VIM''s-NF''s'!I:I,'[1]BASE DE VIM''s-NF''s'!R:R,"") -> 2,454.40 | M26: FINALIZADO
A27: 45903 | B27: Erick | C27: Material | D27: Infraestrutura e elétrica para Secadores, Gerador de Nitrogênio e Chiller | E27: Marco Stella | F27: 1076574932 | G27: 4501708999 | H27: =IF(Table1[[#This Row],[PEDIDO]]<>"",_xlfn.XLOOKUP(Table1[[#This Row],[PEDIDO]],'[1]BASE DE VIM''s-NF''s'!I:I,'[1]BASE DE VIM''s-NF''s'!F:F,"-"),"-") -> 2931482 | I27: =_xlfn.XLOOKUP(Table1[[#This Row],[VIM]],'[1]BASE DE VIM''s-NF''s'!F:F,'[1]BASE DE VIM''s-NF''s'!A:A,"") -> Lançado | J27: =_xlfn.XLOOKUP(Table1[[#This Row],[VIM]],'[1]BASE DE VIM''s-NF''s'!F:F,'[1]BASE DE VIM''s-NF''s'!L:L,"") -> 000003008-9 | K27: =_xlfn.XLOOKUP(Table1[[#This Row],[VIM]],'[1]BASE DE VIM''s-NF''s'!F:F,'[1]BASE DE VIM''s-NF''s'!G:G,"") -> PROCONNECT INSTALACOES LTDA. | L27: =_xlfn.XLOOKUP(Table1[[#This Row],[PEDIDO]],'[1]BASE DE VIM''s-NF''s'!I:I,'[1]BASE DE VIM''s-NF''s'!R:R,"") -> 30,600.00 | M27: FINALIZADO
A28: 45903 | B28: Erick | C28: Material | D28: CAIXAS PARA O TRANSPORTE DE PAPEL | E28: Marco Stella | F28: 1076574965 | G28: 4501709507 | H28: =IF(Table1[[#This Row],[PEDIDO]]<>"",_xlfn.XLOOKUP(Table1[[#This Row],[PEDIDO]],'[1]BASE DE VIM''s-NF''s'!I:I,'[1]BASE DE VIM''s-NF''s'!F:F,"-"),"-") -> 2923948 | I28: =_xlfn.XLOOKUP(Table1[[#This Row],[VIM]],'[1]BASE DE VIM''s-NF''s'!F:F,'[1]BASE DE VIM''s-NF''s'!A:A,"") -> Lançado | J28: =_xlfn.XLOOKUP(Table1[[#This Row],[VIM]],'[1]BASE DE VIM''s-NF''s'!F:F,'[1]BASE DE VIM''s-NF''s'!L:L,"") -> 000125497-1 | K28: =_xlfn.XLOOKUP(Table1[[#This Row],[VIM]],'[1]BASE DE VIM''s-NF''s'!F:F,'[1]BASE DE VIM''s-NF''s'!G:G,"") -> TIAGO DE BROI EIRELI EPP. | L28: =_xlfn.XLOOKUP(Table1[[#This Row],[PEDIDO]],'[1]BASE DE VIM''s-NF''s'!I:I,'[1]BASE DE VIM''s-NF''s'!R:R,"") -> 6,653.00 | M28: FINALIZADO
A29: 45912 | B29: Erick | C29: Material | D29: Torquimetro e Paquimetro | E29: Marco Stella | F29: 1076731871 | G29: 4501710194 | H29: =IF(Table1[[#This Row],[PEDIDO]]<>"",_xlfn.XLOOKUP(Table1[[#This Row],[PEDIDO]],'[1]BASE DE VIM''s-NF''s'!I:I,'[1]BASE DE VIM''s-NF''s'!F:F,"-"),"-") -> 2922687 | I29: =_xlfn.XLOOKUP(Table1[[#This Row],[VIM]],'[1]BASE DE VIM''s-NF''s'!F:F,'[1]BASE DE VIM''s-NF''s'!A:A,"") -> Lançado | J29: =_xlfn.XLOOKUP(Table1[[#This Row],[VIM]],'[1]BASE DE VIM''s-NF''s'!F:F,'[1]BASE DE VIM''s-NF''s'!L:L,"") -> 001464803-3 | K29: =_xlfn.XLOOKUP(Table1[[#This Row],[VIM]],'[1]BASE DE VIM''s-NF''s'!F:F,'[1]BASE DE VIM''s-NF''s'!G:G,"") -> ANHANGUERA COMERCIO DE | L29: =_xlfn.XLOOKUP(Table1[[#This Row],[PEDIDO]],'[1]BASE DE VIM''s-NF''s'!I:I,'[1]BASE DE VIM''s-NF''s'!R:R,"") -> 6,860.71 | M29: FINALIZADO
A30: 45915 | B30: Rafael | C30: Material | D30: Gabarito Pintura | E30: Marco Stella | F30: 1076763643 | G30: 4501710190 | H30: =IF(Table1[[#This Row],[PEDIDO]]<>"",_xlfn.XLOOKUP(Table1[[#This Row],[PEDIDO]],'[1]BASE DE VIM''s-NF''s'!I:I,'[1]BASE DE VIM''s-NF''s'!F:F,"-"),"-") -> 2923546 | I30: =_xlfn.XLOOKUP(Table1[[#This Row],[VIM]],'[1]BASE DE VIM''s-NF''s'!F:F,'[1]BASE DE VIM''s-NF''s'!A:A,"") -> Lançado | J30: =_xlfn.XLOOKUP(Table1[[#This Row],[VIM]],'[1]BASE DE VIM''s-NF''s'!F:F,'[1]BASE DE VIM''s-NF''s'!L:L,"") -> 000001306-1 | K30: =_xlfn.XLOOKUP(Table1[[#This Row],[VIM]],'[1]BASE DE VIM''s-NF''s'!F:F,'[1]BASE DE VIM''s-NF''s'!G:G,"") -> HMTG BRINDES LTDA. | L30: =_xlfn.XLOOKUP(Table1[[#This Row],[PEDIDO]],'[1]BASE DE VIM''s-NF''s'!I:I,'[1]BASE DE VIM''s-NF''s'!R:R,"") -> 1,097.82 | M30: FINALIZADO
A31: 45916 | B31: Rafael | C31: Material | D31: Inspeçao espelho e lanterna | E31: Marco Stella | F31: 1076792855 | G31: 4501710241 | H31: =IF(Table1[[#This Row],[PEDIDO]]<>"",_xlfn.XLOOKUP(Table1[[#This Row],[PEDIDO]],'[1]BASE DE VIM''s-NF''s'!I:I,'[1]BASE DE VIM''s-NF''s'!F:F,"-"),"-") -> 2923433 | I31: =_xlfn.XLOOKUP(Table1[[#This Row],[VIM]],'[1]BASE DE VIM''s-NF''s'!F:F,'[1]BASE DE VIM''s-NF''s'!A:A,"") -> Lançado | J31: =_xlfn.XLOOKUP(Table1[[#This Row],[VIM]],'[1]BASE DE VIM''s-NF''s'!F:F,'[1]BASE DE VIM''s-NF''s'!L:L,"") -> 000125400-1 | K31: =_xlfn.XLOOKUP(Table1[[#This Row],[VIM]],'[1]BASE DE VIM''s-NF''s'!F:F,'[1]BASE DE VIM''s-NF''s'!G:G,"") -> TIAGO DE BROI EIRELI EPP. | L31: =_xlfn.XLOOKUP(Table1[[#This Row],[PEDIDO]],'[1]BASE DE VIM''s-NF''s'!I:I,'[1]BASE DE VIM''s-NF''s'!R:R,"") -> 516.28 | M31: FINALIZADO
A32: 45916 | B32: Rafael | C32: Material | D32: BICO DE SOLDA Ø8 | E32: Marco Stella | F32: 1076792859 | G32: 4501710242 | H32: =IF(Table1[[#This Row],[PEDIDO]]<>"",_xlfn.XLOOKUP(Table1[[#This Row],[PEDIDO]],'[1]BASE DE VIM''s-NF''s'!I:I,'[1]BASE DE VIM''s-NF''s'!F:F,"-"),"-") -> 2927599 | I32: =_xlfn.XLOOKUP(Table1[[#This Row],[VIM]],'[1]BASE DE VIM''s-NF''s'!F:F,'[1]BASE DE VIM''s-NF''s'!A:A,"") -> Lançado | J32: =_xlfn.XLOOKUP(Table1[[#This Row],[VIM]],'[1]BASE DE VIM''s-NF''s'!F:F,'[1]BASE DE VIM''s-NF''s'!L:L,"") -> 000007199-1 | K32: =_xlfn.XLOOKUP(Table1[[#This Row],[VIM]],'[1]BASE DE VIM''s-NF''s'!F:F,'[1]BASE DE VIM''s-NF''s'!G:G,"") -> ROVAMEC USINAGEM LTDA. EPP. | L32: =_xlfn.XLOOKUP(Table1[[#This Row],[PEDIDO]],'[1]BASE DE VIM''s-NF''s'!I:I,'[1]BASE DE VIM''s-NF''s'!R:R,"") -> 2,985.00 | M32: FINALIZADO
A33: 45917 | B33: Rafael | C33: Material | D33: Fita de Arquar e parafusos M12 Bobinagem. | E33: Marco Stella | F33: 1076793131 | G33: 4501710375 | H33: =IF(Table1[[#This Row],[PEDIDO]]<>"",_xlfn.XLOOKUP(Table1[[#This Row],[PEDIDO]],'[1]BASE DE VIM''s-NF''s'!I:I,'[1]BASE DE VIM''s-NF''s'!F:F,"-"),"-") -> 2923949 | I33: =_xlfn.XLOOKUP(Table1[[#This Row],[VIM]],'[1]BASE DE VIM''s-NF''s'!F:F,'[1]BASE DE VIM''s-NF''s'!A:A,"") -> Lançado | J33: =_xlfn.XLOOKUP(Table1[[#This Row],[VIM]],'[1]BASE DE VIM''s-NF''s'!F:F,'[1]BASE DE VIM''s-NF''s'!L:L,"") -> 000125498-1 | K33: =_xlfn.XLOOKUP(Table1[[#This Row],[VIM]],'[1]BASE DE VIM''s-NF''s'!F:F,'[1]BASE DE VIM''s-NF''s'!G:G,"") -> TIAGO DE BROI EIRELI EPP. | L33: =_xlfn.XLOOKUP(Table1[[#This Row],[PEDIDO]],'[1]BASE DE VIM''s-NF''s'!I:I,'[1]BASE DE VIM''s-NF''s'!R:R,"") -> 545.48 | M33: FINALIZADO
... A78: 45993 | B78: Rafael | C78: Material | D78: ANEL ORING SILICONE 29.51 X 5.33 | E78: Marco Stella | F78: 1077637942 | G78: 4501718581 | H78: =IF(Table1[[#This Row],[PEDIDO]]<>"",_xlfn.XLOOKUP(Table1[[#This Row],[PEDIDO]],'[1]BASE DE VIM''s-NF''s'!I:I,'[1]BASE DE VIM''s-NF''s'!F:F,"-"),"-") -> 2949513 | I78: =_xlfn.XLOOKUP(Table1[[#This Row],[VIM]],'[1]BASE DE VIM''s-NF''s'!F:F,'[1]BASE DE VIM''s-NF''s'!A:A,"") -> Lançado | J78: =_xlfn.XLOOKUP(Table1[[#This Row],[VIM]],'[1]BASE DE VIM''s-NF''s'!F:F,'[1]BASE DE VIM''s-NF''s'!L:L,"") -> 000130280-1 | K78: =_xlfn.XLOOKUP(Table1[[#This Row],[VIM]],'[1]BASE DE VIM''s-NF''s'!F:F,'[1]BASE DE VIM''s-NF''s'!G:G,"") -> TIAGO DE BROI EIRELI EPP. | L78: =_xlfn.XLOOKUP(Table1[[#This Row],[PEDIDO]],'[1]BASE DE VIM''s-NF''s'!I:I,'[1]BASE DE VIM''s-NF''s'!R:R,"") -> 1,940.00 | M78: FINALIZADO
A79: 45993 | B79: Erick | C79: Serviço | D79: Programação célula de emborrachamento | E79: Marco Stella | F79: 1077637913 | G79: 4501718745 | H79: =IF(Table1[[#This Row],[PEDIDO]]<>"",_xlfn.XLOOKUP(Table1[[#This Row],[PEDIDO]],'[1]BASE DE VIM''s-NF''s'!I:I,'[1]BASE DE VIM''s-NF''s'!F:F,"-"),"-") -> 2962348 | J79: =_xlfn.XLOOKUP(Table1[[#This Row],[VIM]],'[1]BASE DE VIM''s-NF''s'!F:F,'[1]BASE DE VIM''s-NF''s'!L:L,"") -> 000000396-9 | K79: =_xlfn.XLOOKUP(Table1[[#This Row],[VIM]],'[1]BASE DE VIM''s-NF''s'!F:F,'[1]BASE DE VIM''s-NF''s'!G:G,"") -> DCSPRO - AUTOMACAO PROJETOS E | L79: =_xlfn.XLOOKUP(Table1[[#This Row],[PEDIDO]],'[1]BASE DE VIM''s-NF''s'!I:I,'[1]BASE DE VIM''s-NF''s'!R:R,"") -> 7,800.00 | M79: FINALIZADO
A80: 45993 | B80: Rafael | C80: Material | D80: Carrinho para o microondas Papel | E80: Marco Stella | F80: 1077650862 | G80: 4501718864 | H80: =IF(Table1[[#This Row],[PEDIDO]]<>"",_xlfn.XLOOKUP(Table1[[#This Row],[PEDIDO]],'[1]BASE DE VIM''s-NF''s'!I:I,'[1]BASE DE VIM''s-NF''s'!F:F,"-"),"-") -> 2947169 | I80: =_xlfn.XLOOKUP(Table1[[#This Row],[VIM]],'[1]BASE DE VIM''s-NF''s'!F:F,'[1]BASE DE VIM''s-NF''s'!A:A,"") -> Lançado | J80: =_xlfn.XLOOKUP(Table1[[#This Row],[VIM]],'[1]BASE DE VIM''s-NF''s'!F:F,'[1]BASE DE VIM''s-NF''s'!L:L,"") -> 001502452-3 | K80: =_xlfn.XLOOKUP(Table1[[#This Row],[VIM]],'[1]BASE DE VIM''s-NF''s'!F:F,'[1]BASE DE VIM''s-NF''s'!G:G,"") -> ANHANGUERA COMERCIO DE | L80: =_xlfn.XLOOKUP(Table1[[#This Row],[PEDIDO]],'[1]BASE DE VIM''s-NF''s'!I:I,'[1]BASE DE VIM''s-NF''s'!R:R,"") -> 566.09 | M80: FINALIZADO
A81: 45993 | B81: Rafael | C81: Material | D81: Chave hexagonal t e agulhas e bico de fluido | E81: Marco Stella | F81: 1077650864 | G81: 4501718866 | H81: =IF(Table1[[#This Row],[PEDIDO]]<>"",_xlfn.XLOOKUP(Table1[[#This Row],[PEDIDO]],'[1]BASE DE VIM''s-NF''s'!I:I,'[1]BASE DE VIM''s-NF''s'!F:F,"-"),"-") -> 2951605 | I81: =_xlfn.XLOOKUP(Table1[[#This Row],[VIM]],'[1]BASE DE VIM''s-NF''s'!F:F,'[1]BASE DE VIM''s-NF''s'!A:A,"") -> Lançado | J81: =_xlfn.XLOOKUP(Table1[[#This Row],[VIM]],'[1]BASE DE VIM''s-NF''s'!F:F,'[1]BASE DE VIM''s-NF''s'!L:L,"") -> 001508003-3 | K81: =_xlfn.XLOOKUP(Table1[[#This Row],[VIM]],'[1]BASE DE VIM''s-NF''s'!F:F,'[1]BASE DE VIM''s-NF''s'!G:G,"") -> ANHANGUERA COMERCIO DE | L81: =_xlfn.XLOOKUP(Table1[[#This Row],[PEDIDO]],'[1]BASE DE VIM''s-NF''s'!I:I,'[1]BASE DE VIM''s-NF''s'!R:R,"") -> 321.37 | M81: FINALIZADO
A82: 45993 | B82: Fernanda | C82: Material | D82: Ferramenta de crimpar e espatula | E82: Marco Stella | F82: 1077663386 | G82: 4501719453 | H82: =IF(Table1[[#This Row],[PEDIDO]]<>"",_xlfn.XLOOKUP(Table1[[#This Row],[PEDIDO]],'[1]BASE DE VIM''s-NF''s'!I:I,'[1]BASE DE VIM''s-NF''s'!F:F,"-"),"-") -> 2949512 | I82: =_xlfn.XLOOKUP(Table1[[#This Row],[VIM]],'[1]BASE DE VIM''s-NF''s'!F:F,'[1]BASE DE VIM''s-NF''s'!A:A,"") -> Lançado | J82: =_xlfn.XLOOKUP(Table1[[#This Row],[VIM]],'[1]BASE DE VIM''s-NF''s'!F:F,'[1]BASE DE VIM''s-NF''s'!L:L,"") -> 000130276-1 | K82: =_xlfn.XLOOKUP(Table1[[#This Row],[VIM]],'[1]BASE DE VIM''s-NF''s'!F:F,'[1]BASE DE VIM''s-NF''s'!G:G,"") -> TIAGO DE BROI EIRELI EPP. | L82: =_xlfn.XLOOKUP(Table1[[#This Row],[PEDIDO]],'[1]BASE DE VIM''s-NF''s'!I:I,'[1]BASE DE VIM''s-NF''s'!R:R,"") -> 1,991.36 | M82: FINALIZADO
A83: 45993 | B83: Fernanda | C83: Material | D83: Ferramentas montagem de rack e lanterna | E83: Marco Stella | F83: 1077663390 | G83: 4501719454 | H83: =IF(Table1[[#This Row],[PEDIDO]]<>"",_xlfn.XLOOKUP(Table1[[#This Row],[PEDIDO]],'[1]BASE DE VIM''s-NF''s'!I:I,'[1]BASE DE VIM''s-NF''s'!F:F,"-"),"-") -> 2950785 | I83: =_xlfn.XLOOKUP(Table1[[#This Row],[VIM]],'[1]BASE DE VIM''s-NF''s'!F:F,'[1]BASE DE VIM''s-NF''s'!A:A,"") -> Lançado | J83: =_xlfn.XLOOKUP(Table1[[#This Row],[VIM]],'[1]BASE DE VIM''s-NF''s'!F:F,'[1]BASE DE VIM''s-NF''s'!L:L,"") -> 000130507-1 | K83: =_xlfn.XLOOKUP(Table1[[#This Row],[VIM]],'[1]BASE DE VIM''s-NF''s'!F:F,'[1]BASE DE VIM''s-NF''s'!G:G,"") -> TIAGO DE BROI EIRELI EPP. | L83: =_xlfn.XLOOKUP(Table1[[#This Row],[PEDIDO]],'[1]BASE DE VIM''s-NF''s'!I:I,'[1]BASE DE VIM''s-NF''s'!R:R,"") -> 539.98 | M83: FINALIZADO
A84: 46000 | B84: Rafael | C84: Material | D84: Placas de Naylon | E84: Marco Stella | F84: 1077671835 | G84: 4501719457 | H84: =IF(Table1[[#This Row],[PEDIDO]]<>"",_xlfn.XLOOKUP(Table1[[#This Row],[PEDIDO]],'[1]BASE DE VIM''s-NF''s'!I:I,'[1]BASE DE VIM''s-NF''s'!F:F,"-"),"-") -> 2950241 | I84: =_xlfn.XLOOKUP(Table1[[#This Row],[VIM]],'[1]BASE DE VIM''s-NF''s'!F:F,'[1]BASE DE VIM''s-NF''s'!A:A,"") -> Lançado | J84: =_xlfn.XLOOKUP(Table1[[#This Row],[VIM]],'[1]BASE DE VIM''s-NF''s'!F:F,'[1]BASE DE VIM''s-NF''s'!L:L,"") -> 000007270-1 | K84: =_xlfn.XLOOKUP(Table1[[#This Row],[VIM]],'[1]BASE DE VIM''s-NF''s'!F:F,'[1]BASE DE VIM''s-NF''s'!G:G,"") -> ROVAMEC USINAGEM LTDA. EPP. | L84: =_xlfn.XLOOKUP(Table1[[#This Row],[PEDIDO]],'[1]BASE DE VIM''s-NF''s'!I:I,'[1]BASE DE VIM''s-NF''s'!R:R,"") -> 3,980.00 | M84: FINALIZADO
...
